Workbook

Sheet Prioritization
B1: Company Target Prioritization
B2: Industry | C2: Average Grading | D2: Average grading if willing to use 3rd Party | I2: Phase 1 | J2: Low data maturity, limited data exchange
B3: Manufacturer | C3: =SUMIF(Table1[Industry],B3,Table1[Grade])/COUNTIF(Table1[Industry],B3) -> 5.8 | D3: =IFERROR(SUMIFS(Table1[Grade],Table1[Industry],B3,Table1[Third Party],">3")/COUNTIFS(Table1[Industry],B3,Table1[Third Party],">3"),"") -> 7.5 | I3: Phase 2 | J3: Medium data maturity, some data exchange
B4: Specialty Retail | C4: =SUMIF(Table1[Industry],B4,Table1[Grade])/COUNTIF(Table1[Industry],B4) -> 5.8333333 | D4: =IFERROR(SUMIFS(Table1[Grade],Table1[Industry],B4,Table1[Third Party],">3")/COUNTIFS(Table1[Industry],B4,Table1[Third Party],">3"),"") -> 8 | I4: Phase 3 | J4: High data maturity, existing data exchange
B5: Wholesaler | C5: =SUMIF(Table1[Industry],B5,Table1[Grade])/COUNTIF(Table1[Industry],B5) -> 4.5 | D5: =IFERROR(SUMIFS(Table1[Grade],Table1[Industry],B5,Table1[Third Party],">3")/COUNTIFS(Table1[Industry],B5,Table1[Third Party],">3"),"") -> 5
B6: Retailer | C6: =SUMIF(Table1[Industry],B6,Table1[Grade])/COUNTIF(Table1[Industry],B6) -> 3 | D6: =IFERROR(SUMIFS(Table1[Grade],Table1[Industry],B6,Table1[Third Party],">3")/COUNTIFS(Table1[Industry],B6,Table1[Third Party],">3"),"")
D8: 1=Low maturity | E8: 5=high maturity | G8: 0-10
B9: Company | C9: Industry | D9: Data Maturity | E9: Collaboration | F9: Third Party | G9: Grade | H9: Notes | I9: Starting Phase | J9: Contact
B10: Dico Foods | C10: Manufacturer | D10: 1 | E10: 5 | F10: 5 | G10: 8.5 | I10: Phase 1
B11: Familia Pharmacies | C11: Specialty Retail | D11: 1 | E11: 5 | F11: 5 | G11: 8.5 | I11: Phase 1
B12: Spuntini | C12: Wholesaler | D12: 2 | E12: 5 | F12: 5 | G12: 8.5 | I12: Phase 2
B13: Tom & Co | C13: Specialty Retail | D13: 4 | E13: 4 | F13: 5 | G13: 7.5 | I13: Phase 2
B14: Edgard & Cooper | C14: Manufacturer | D14: 5 | E14: 3 | F14: 5 | G14: 7 | I14: Phase 3
B15: Wellness Pet | C15: Manufacturer | D15: 3 | E15: 5 | F15: 5 | G15: 7 | I15: Phase 1
B16: Arla | C16: Manufacturer | D16: 3 | E16: 5 | F16: 3 | G16: 6.5 | I16: Phase 2
B17: Conway | C17: Wholesaler | D17: 3 | E17: 5 | F17: 5 | G17: 5 | H17: Gondola wholesale market data | I17: No Go
B18: Solucious | C18: Wholesaler | D18: 5 | E18: 5 | F18: 3 | G18: 3 | H18: Piloting already with a company (Gondola? ) | I18: No Go
B19: Shell | C19: Specialty Retail | D19: 5 | E19: 1 | F19: 1 | G19: 1.5 | H19: Exited Nielsen data sharing 20 years ago | I19: No Go
B20: Hanos | C20: Wholesaler | D20: 3 | E20: 5 | F20: 5 | G20: 1.5 | H20: Limiting Company Policy | I20: No Go
B21: Spadel | C21: Manufacturer | D21: 5 | E21: 5 | F21: 1 | G21: 0 | H21: Limiting Company Policy | I21: No Go
B22: Lidl | C22: Retailer | D22: 5 | E22: 2 | F22: 3 | G22: 3 | H22: Limiting Company Policy | I22: Phase 2
C46: Target audience:
D47: 1) Standalone | F47: 1) Combined | I47: 1) Combined
D48: 2) Combined

Sheet Scores
A1: Tool Target Prioritization
F2: ='Analysis — Filter View'!E37 -> 17 | H2: Average Score by Industry | M2: Percentage by Industry
A3: Section | B3: Question ID | C3: Question | D3: Range | E3: Value | F3: % | H3: Manufacturer | I3: Specialty Retail | J3: Wholesaler | K3: Retailer | M3: Manufacturer | N3: Specialty Retail | O3: Wholesaler | P3: Retailer | Q3: Notes
A4: Baseline | B4: B1_INTEREST | C4: Interest (1–10) | D4: 0-1 | E4: {=TRANSPOSE('Analysis — Filter View'!H37:AP37)} -> 7.1923077 | H4: {=TRANSPOSE('Analysis — Filter View'!H38:AP38)} -> 8.4 | I4: {=TRANSPOSE('Analysis — Filter View'!H39:AP39)} -> 6 | J4: {=TRANSPOSE('Analysis — Filter View'!H40:AP40)} -> 7.625 | K4: {=TRANSPOSE('Analysis — Filter View'!H41:AP41)} -> 3 | Q4: Prioiritize Manufacturer > Wholesaer > Specialty Retailer > Retail
A5: Baseline | B5: B2_SHARING | C5: Shares data (0/1) | D5: 0-1 | E5: 13 | F5: =E5/$F$2 -> 0.76470588 | H5: 5 | I5: 3 | J5: 4 | K5: 1 | M5: =H5/'Analysis — Filter View'!$E$38 -> 1 | N5: =I5/'Analysis — Filter View'!$E$39 -> 1 | O5: =J5/'Analysis — Filter View'!$E$40 -> 1 | P5: =K5/'Analysis — Filter View'!$E$41 -> 1 | Q5: Everyone shares some sort of data in the market.
A6: Baseline | B6: B3_MONETIZE | C6: Monetizes data (0/1) | D6: 0-1 | E6: 4 | F6: =E6/$F$2 -> 0.23529412 | H6: 0 | I6: 1 | J6: 3 | K6: 0 | M6: =H6/'Analysis — Filter View'!$E$38 -> 0 | N6: =I6/'Analysis — Filter View'!$E$39 -> 0.33333333 | O6: =J6/'Analysis — Filter View'!$E$40 -> 0.75 | P6: =K6/'Analysis — Filter View'!$E$41 -> 0 | Q6: Data monetization is a critical strategic choice for retail and manufacturers, and some specialty retailers
A7: Baseline | B7: B4_STRATEGIC | C7: Strategic reasons (0/1) | D7: 0-1 | E7: 7 | F7: =E7/$F$2 -> 0.41176471 | H7: 3 | I7: 1 | J7: 2 | K7: 1 | M7: =H7/'Analysis — Filter View'!$E$38 -> 0.6 | N7: =I7/'Analysis — Filter View'!$E$39 -> 0.33333333 | O7: =J7/'Analysis — Filter View'!$E$40 -> 0.5 | P7: =K7/'Analysis — Filter View'!$E$41 -> 1 | Q7: Data sharing is a strategic choice.
A8: Maturity | B8: M1_AUTOMATED | C8: Automated vs manual | D8: 0-5 | E8: 2.7272727 | H8: 3 | I8: 1.3333333 | J8: 2.75 | K8: 0
A9: Maturity | B9: M2_REALTIME | C9: Real-time vs lagging | D9: 0-5 | E9: 2.3636364 | H9: 2.6 | I9: 1 | J9: 2.5 | K9: 0
A10: Maturity | B10: M3_STRATEGIC | C10: Ops vs strategic focus | D10: 0-5 | E10: 3.2307692 | H10: 3.8 | I10: 1.6666667 | J10: 4 | K10: 2
A11: Maturity | B11: M4_BREADTH | C11: All clients vs selective | D11: 0-5 | E11: 2.6153846 | H11: 3.2 | I11: 1.6666667 | J11: 3 | K11: 1
A12: Maturity | B12: M5_DATATYPES | C12: Breadth of data | D12: 0-5 | E12: 3.2307692 | H12: 4 | I12: 1.6666667 | J12: 3.75 | K12: 2
A13: Maturity | B13: M6_TRUST | C13: Trust in data | D13: 0-5 | E13: 2.6666667 | H13: 2.6 | I13: 1.3333333 | J13: 1.75 | K13: 0
A14: Maturity | B14: M7_BARRIERS | C14: Readiness/barriers | D14: 0-5 | E14: 3.6153846 | H14: 4 | I14: 3.3333333 | J14: 3.25 | K14: 4
A15: Maturity | B15: M8_IMPACT | C15: Operational impact | D15: 0-5 | E15: 3.3333333 | H15: 3.2 | I15: 0 | J15: 2.5 | K15: 4 | Q15: The operational inefficiencies have higher impact (to be tested further) on the retail side > sell-in opportunities missed
A16: Maturity | B16: M9_WILLINGNESS | C16: Willingness (synthesis) | D16: 0-5 | E16: 6.9230769 | H16: 8 | I16: 5.6666667 | J16: 7.5 | K16: 3 | Q16: Manufacturers have higher willingness to collaborate on data & insights. Should be the primary contact to push for collaboration.
A17: Value Unlock | B17: SV1_PRICING | C17: Pricing | D17: 0-1 | E17: 7 | F17: =E17/$F$2 -> 0.41176471 | H17: 4 | I17: 1 | J17: 2 | K17: 0 | M17: =H17/'Analysis — Filter View'!$E$38 -> 0.8 | N17: =I17/'Analysis — Filter View'!$E$39 -> 0.33333333 | O17: =J17/'Analysis — Filter View'!$E$40 -> 0.5 | P17: =K17/'Analysis — Filter View'!$E$41 -> 0 | Q17: Value driver #5
A18: Value Unlock | B18: SV2_PROMOTIONS | C18: Promotions | D18: 0-1 | E18: 8 | F18: =E18/$F$2 -> 0.47058824 | H18: 4 | I18: 1 | J18: 2 | K18: 1 | M18: =H18/'Analysis — Filter View'!$E$38 -> 0.8 | N18: =I18/'Analysis — Filter View'!$E$39 -> 0.33333333 | O18: =J18/'Analysis — Filter View'!$E$40 -> 0.5 | P18: =K18/'Analysis — Filter View'!$E$41 -> 1 | Q18: Value driver #2
A19: Value Unlock | B19: SV3_SUPPLYCHAIN | C19: Supply Chain | D19: 0-1 | E19: 8 | F19: =E19/$F$2 -> 0.47058824 | H19: 4 | I19: 2 | J19: 1 | K19: 1 | M19: =H19/'Analysis — Filter View'!$E$38 -> 0.8 | N19: =I19/'Analysis — Filter View'!$E$39 -> 0.66666667 | O19: =J19/'Analysis — Filter View'!$E$40 -> 0.25 | P19: =K19/'Analysis — Filter View'!$E$41 -> 1 | Q19: Value driver #1
A20: Value Unlock | B20: SV4_CATEGORY | C20: Category Planning | D20: 0-1 | E20: 10 | F20: =E20/$F$2 -> 0.58823529 | H20: 4 | I20: 2 | J20: 4 | K20: 0 | M20: =H20/'Analysis — Filter View'!$E$38 -> 0.8 | N20: =I20/'Analysis — Filter View'!$E$39 -> 0.66666667 | O20: =J20/'Analysis — Filter View'!$E$40 -> 1 | P20: =K20/'Analysis — Filter View'!$E$41 -> 0 | Q20: Value driver #3
A21: Value Unlock | B21: SV5_DEMAND | C21: Demand Forecasting | D21: 0-1 | E21: 4 | F21: =E21/$F$2 -> 0.23529412 | H21: 2 | I21: 0 | J21: 1 | K21: 1 | M21: =H21/'Analysis — Filter View'!$E$38 -> 0.4 | N21: =I21/'Analysis — Filter View'!$E$39 -> 0 | O21: =J21/'Analysis — Filter View'!$E$40 -> 0.25 | P21: =K21/'Analysis — Filter View'!$E$41 -> 1 | Q21: Value driver #4
A22: Value Unlock | B22: SV6_ACCOUNT | C22: Accountability | D22: 0-1 | E22: 3 | F22: =E22/$F$2 -> 0.17647059 | H22: 2 | I22: 0 | J22: 1 | K22: 0 | M22: =H22/'Analysis — Filter View'!$E$38 -> 0.4 | N22: =I22/'Analysis — Filter View'!$E$39 -> 0 | O22: =J22/'Analysis — Filter View'!$E$40 -> 0.25 | P22: =K22/'Analysis — Filter View'!$E$41 -> 0 | Q22: Value driver #7
A23: Value Unlock | B23: SV7_OPS | C23: Operationalization | D23: 0-1 | E23: 5 | F23: =E23/$F$2 -> 0.29411765 | H23: 3 | I23: 0 | J23: 2 | K23: 0 | M23: =H23/'Analysis — Filter View'!$E$38 -> 0.6 | N23: =I23/'Analysis — Filter View'!$E$39 -> 0 | O23: =J23/'Analysis — Filter View'!$E$40 -> 0.5 | P23: =K23/'Analysis — Filter View'!$E$41 -> 0 | Q23: Value driver #6
A24: Concerns | B24: SC1_DATASENS | C24: Data Sensitivity | D24: 0-1 | E24: 12 | F24: =E24/$F$2 -> 0.70588235 | H24: 5 | I24: 3 | J24: 3 | K24: 1 | M24: =H24/'Analysis — Filter View'!$E$38 -> 1 | N24: =I24/'Analysis — Filter View'!$E$39 -> 1 | O24: =J24/'Analysis — Filter View'!$E$40 -> 0.75 | P24: =K24/'Analysis — Filter View'!$E$41 -> 1 | Q24: Concern #1
A25: Concerns | B25: SC2_COMPLIANCE | C25: Compliance | D25: 0-1 | E25: 8 | F25: =E25/$F$2 -> 0.47058824 | H25: 4 | I25: 1 | J25: 2 | K25: 1 | M25: =H25/'Analysis — Filter View'!$E$38 -> 0.8 | N25: =I25/'Analysis — Filter View'!$E$39 -> 0.33333333 | O25: =J25/'Analysis — Filter View'!$E$40 -> 0.5 | P25: =K25/'Analysis — Filter View'!$E$41 -> 1 | Q25: Concern #2
A26: Concerns | B26: SC3_TRUST | C26: Trust Issues | D26: 0-1 | E26: 5 | F26: =E26/$F$2 -> 0.29411765 | H26: 3 | I26: 0 | J26: 2 | K26: 0 | M26: =H26/'Analysis — Filter View'!$E$38 -> 0.6 | N26: =I26/'Analysis — Filter View'!$E$39 -> 0 | O26: =J26/'Analysis — Filter View'!$E$40 -> 0.5 | P26: =K26/'Analysis — Filter View'!$E$41 -> 0 | Q26: Concern #4
A27: Concerns | B27: SC4_DATAPROC | C27: Data Processing | D27: 0-1 | E27: 9 | F27: =E27/$F$2 -> 0.52941176 | H27: 4 | I27: 2 | J27: 3 | K27: 0 | M27: =H27/'Analysis — Filter View'!$E$38 -> 0.8 | N27: =I27/'Analysis — Filter View'!$E$39 -> 0.66666667 | O27: =J27/'Analysis — Filter View'!$E$40 -> 0.75 | P27: =K27/'Analysis — Filter View'!$E$41 -> 0 | Q27: Concern #3
A28: Tool Features | B28: SF1_REALTIME | C28: Real-time exchange | D28: 0-1 | E28: 5 | F28: =E28/$F$2 -> 0.29411765 | H28: 3 | I28: 0 | J28: 2 | K28: 0 | M28: =H28/'Analysis — Filter View'!$E$38 -> 0.6 | N28: =I28/'Analysis — Filter View'!$E$39 -> 0 | O28: =J28/'Analysis — Filter View'!$E$40 -> 0.5 | P28: =K28/'Analysis — Filter View'!$E$41 -> 0 | Q28: Feature #3
... A38: Datasets | B38: SD6_CONJOINT | C38: Conjoint names | D38: 0-1 | E38: 0 | F38: =E38/$F$2 -> 0 | H38: 0 | I38: 0 | J38: 0 | K38: 0 | M38: =H38/'Analysis — Filter View'!$E$38 -> 0 | N38: =I38/'Analysis — Filter View'!$E$39 -> 0 | O38: =J38/'Analysis — Filter View'!$E$40 -> 0 | P38: =K38/'Analysis — Filter View'!$E$41 -> 0 | Q38: Collab data #6

Sheet Analysis — Filter View
B1: Filter View — Companies as Rows
H2: Baseline | L2: Maturity | U2: Value Unlock | AB2: Concerns | AF2: Tool Features | AK2: Datasets
B3: Company | C3: Role | D3: Industry | E3: Sub-Industry | F3: Size | G3: Country | H3: Interest (1–10) | I3: Shares data (0/1) | J3: Monetizes data (0/1) | K3: Strategic reasons (0/1) | L3: Automated vs manual | M3: Real-time vs lagging | N3: Ops vs strategic focus | O3: All clients vs selective | P3: Breadth of data | Q3: Trust in data | R3: Readiness/barriers | S3: Operational impact | T3: Willingness (synthesis) | U3: Pricing | V3: Promotions | W3: Supply Chain | X3: Category Planning | Y3: Demand Forecasting | Z3: Accountability | AA3: Operationalization | AB3: Data Sensitivity | AC3: Compliance | AD3: Trust Issues | AE3: Data Processing | AF3: Real-time exchange | AG3: Equal access | AH3: Simple UX/UI | AI3: Joint decisions | AJ3: Masking rules | AK3: Global trends | AL3: Market research | AM3: Category perf. | AN3: Shipments | AO3: Lead times | AP3: Conjoint names
B4: Company 1 | C4: =IFERROR(VLOOKUP("Interviewee Position",'Company 1'!$B:$C,2,0),"") -> Chief of Staff | D4: =IFERROR(VLOOKUP("Company Industry",'Company 1'!$B:$C,2,0),"") -> Specialty Retail | E4: =IFERROR(VLOOKUP("Company Sub-Industry",'Company 1'!$B:$C,2,0),"") -> Specialty Retail | F4: =IFERROR(VLOOKUP("Company Size (Turnover)",'Company 1'!$B:$C,2,0),"") -> 160000000 | G4: =IFERROR(VLOOKUP("Country",'Company 1'!$B:$C,2,0),"") -> Belgium | H4: =IFERROR(VLOOKUP("B1_INTEREST",'Company 1'!$B:$E,4,0),"") -> 7 | I4: =IFERROR(VLOOKUP("B2_SHARING",'Company 1'!$B:$E,4,0),"") -> 1 | J4: =IFERROR(VLOOKUP("B3_MONETIZE",'Company 1'!$B:$E,4,0),"") -> 1 | K4: =IFERROR(VLOOKUP("B4_STRATEGIC",'Company 1'!$B:$E,4,0),"") -> 0 | L4: =IFERROR(VLOOKUP("M1_AUTOMATED",'Company 1'!$B:$E,4,0),"") -> 3 | M4: =IFERROR(VLOOKUP("M2_REALTIME",'Company 1'!$B:$E,4,0),"") -> 2 | N4: =IFERROR(VLOOKUP("M3_STRATEGIC",'Company 1'!$B:$E,4,0),"") -> 2 | O4: =IFERROR(VLOOKUP("M4_BREADTH",'Company 1'!$B:$E,4,0),"") -> 2 | P4: =IFERROR(VLOOKUP("M5_DATATYPES",'Company 1'!$B:$E,4,0),"") -> 2 | Q4: =IFERROR(VLOOKUP("M6_TRUST",'Company 1'!$B:$E,4,0),"") -> 4 | R4: =IFERROR(VLOOKUP("M7_BARRIERS",'Company 1'!$B:$E,4,0),"") -> 3 | S4: =IFERROR(VLOOKUP("M8_IMPACT",'Company 1'!$B:$E,4,0),"") -> 0 | T4: =IFERROR(VLOOKUP("M9_WILLINGNESS",'Company 1'!$B:$E,4,0),"") -> 6 | U4: =IFERROR(VLOOKUP("SV1_PRICING",'Company 1'!$B:$E,4,0),"") -> 0 | V4: =IFERROR(VLOOKUP("SV2_PROMOTIONS",'Company 1'!$B:$E,4,0),"") -> 0 | W4: =IFERROR(VLOOKUP("SV3_SUPPLYCHAIN",'Company 1'!$B:$E,4,0),"") -> 0 | X4: =IFERROR(VLOOKUP("SV4_CATEGORY",'Company 1'!$B:$E,4,0),"") -> 1 | Y4: =IFERROR(VLOOKUP("SV5_DEMAND",'Company 1'!$B:$E,4,0),"") -> 0 | Z4: =IFERROR(VLOOKUP("SV6_ACCOUNT",'Company 1'!$B:$E,4,0),"") -> 0 | AA4: =IFERROR(VLOOKUP("SV7_OPS",'Company 1'!$B:$E,4,0),"") -> 0 | AB4: =IFERROR(VLOOKUP("SC1_DATASENS",'Company 1'!$B:$E,4,0),"") -> 1 | AC4: =IFERROR(VLOOKUP("SC2_COMPLIANCE",'Company 1'!$B:$E,4,0),"") -> 0 | AD4: =IFERROR(VLOOKUP("SC3_TRUST",'Company 1'!$B:$E,4,0),"") -> 0 | AE4: =IFERROR(VLOOKUP("SC4_DATAPROC",'Company 1'!$B:$E,4,0),"") -> 0 | AF4: =IFERROR(VLOOKUP("SF1_REALTIME",'Company 1'!$B:$E,4,0),"") -> 0 | AG4: =IFERROR(VLOOKUP("SF2_ACCESS",'Company 1'!$B:$E,4,0),"") -> 0 | AH4: =IFERROR(VLOOKUP("SF3_UX",'Company 1'!$B:$E,4,0),"") -> 0 | AI4: =IFERROR(VLOOKUP("SF4_DECISION",'Company 1'!$B:$E,4,0),"") -> 0 | AJ4: =IFERROR(VLOOKUP("SF5_MASKING",'Company 1'!$B:$E,4,0),"") -> 1 | AK4: =IFERROR(VLOOKUP("SD1_TRENDS",'Company 1'!$B:$E,4,0),"") -> 1 | AL4: =IFERROR(VLOOKUP("SD2_MARKET",'Company 1'!$B:$E,4,0),"") -> 1 | AM4: =IFERROR(VLOOKUP("SD3_CATEGORY",'Company 1'!$B:$E,4,0),"") -> 1 | AN4: =IFERROR(VLOOKUP("SD4_SHIPMENT",'Company 1'!$B:$E,4,0),"") -> 0 | AO4: =IFERROR(VLOOKUP("SD5_LEAD",'Company 1'!$B:$E,4,0),"") -> 0 | AP4: =IFERROR(VLOOKUP("SD6_CONJOINT",'Company 1'!$B:$E,4,0),"") -> 0
B5: Company 2 | C5: =IFERROR(VLOOKUP("Interviewee Position",'Company 2'!$B:$C,2,0),"") -> President and Managing Director Belgian Shell | D5: =IFERROR(VLOOKUP("Company Industry",'Company 2'!$B:$C,2,0),"") -> Oil & Gas | E5: =IFERROR(VLOOKUP("Company Sub-Industry",'Company 2'!$B:$C,2,0),"") -> Specialty Retail | F5: =IFERROR(VLOOKUP("Company Size (Turnover)",'Company 2'!$B:$C,2,0),"") -> 2000000000 | G5: =IFERROR(VLOOKUP("Country",'Company 2'!$B:$C,2,0),"") -> UK | H5: =IFERROR(VLOOKUP("B1_INTEREST",'Company 2'!$B:$E,4,0),"") -> 2 | I5: =IFERROR(VLOOKUP("B2_SHARING",'Company 2'!$B:$E,4,0),"") -> 1 | J5: =IFERROR(VLOOKUP("B3_MONETIZE",'Company 2'!$B:$E,4,0),"") -> 0 | K5: =IFERROR(VLOOKUP("B4_STRATEGIC",'Company 2'!$B:$E,4,0),"") -> 1 | L5: =IFERROR(VLOOKUP("M1_AUTOMATED",'Company 2'!$B:$E,4,0),"") -> 0 | M5: =IFERROR(VLOOKUP("M2_REALTIME",'Company 2'!$B:$E,4,0),"") -> 0 | N5: =IFERROR(VLOOKUP("M3_STRATEGIC",'Company 2'!$B:$E,4,0),"") -> 1 | O5: =IFERROR(VLOOKUP("M4_BREADTH",'Company 2'!$B:$E,4,0),"") -> 1 | P5: =IFERROR(VLOOKUP("M5_DATATYPES",'Company 2'!$B:$E,4,0),"") -> 1 | Q5: =IFERROR(VLOOKUP("M6_TRUST",'Company 2'!$B:$E,4,0),"") -> 0 | R5: =IFERROR(VLOOKUP("M7_BARRIERS",'Company 2'!$B:$E,4,0),"") -> 5 | S5: =IFERROR(VLOOKUP("M8_IMPACT",'Company 2'!$B:$E,4,0),"") -> 0 | T5: =IFERROR(VLOOKUP("M9_WILLINGNESS",'Company 2'!$B:$E,4,0),"") -> 2 | U5: =IFERROR(VLOOKUP("SV1_PRICING",'Company 2'!$B:$E,4,0),"") -> 0 | V5: =IFERROR(VLOOKUP("SV2_PROMOTIONS",'Company 2'!$B:$E,4,0),"") -> 0 | W5: =IFERROR(VLOOKUP("SV3_SUPPLYCHAIN",'Company 2'!$B:$E,4,0),"") -> 1 | X5: =IFERROR(VLOOKUP("SV4_CATEGORY",'Company 2'!$B:$E,4,0),"") -> 0 | Y5: =IFERROR(VLOOKUP("SV5_DEMAND",'Company 2'!$B:$E,4,0),"") -> 0 | Z5: =IFERROR(VLOOKUP("SV6_ACCOUNT",'Company 2'!$B:$E,4,0),"") -> 0 | AA5: =IFERROR(VLOOKUP("SV7_OPS",'Company 2'!$B:$E,4,0),"") -> 0 | AB5: =IFERROR(VLOOKUP("SC1_DATASENS",'Company 2'!$B:$E,4,0),"") -> 1 | AC5: =IFERROR(VLOOKUP("SC2_COMPLIANCE",'Company 2'!$B:$E,4,0),"") -> 1 | AD5: =IFERROR(VLOOKUP("SC3_TRUST",'Company 2'!$B:$E,4,0),"") -> 0 | AE5: =IFERROR(VLOOKUP("SC4_DATAPROC",'Company 2'!$B:$E,4,0),"") -> 1 | AF5: =IFERROR(VLOOKUP("SF1_REALTIME",'Company 2'!$B:$E,4,0),"") -> 0 | AG5: =IFERROR(VLOOKUP("SF2_ACCESS",'Company 2'!$B:$E,4,0),"") -> 0 | AH5: =IFERROR(VLOOKUP("SF3_UX",'Company 2'!$B:$E,4,0),"") -> 0 | AI5: =IFERROR(VLOOKUP("SF4_DECISION",'Company 2'!$B:$E,4,0),"") -> 0 | AJ5: =IFERROR(VLOOKUP("SF5_MASKING",'Company 2'!$B:$E,4,0),"") -> 1 | AK5: =IFERROR(VLOOKUP("SD1_TRENDS",'Company 2'!$B:$E,4,0),"") -> 0 | AL5: =IFERROR(VLOOKUP("SD2_MARKET",'Company 2'!$B:$E,4,0),"") -> 1 | AM5: =IFERROR(VLOOKUP("SD3_CATEGORY",'Company 2'!$B:$E,4,0),"") -> 0 | AN5: =IFERROR(VLOOKUP("SD4_SHIPMENT",'Company 2'!$B:$E,4,0),"") -> 0 | AO5: =IFERROR(VLOOKUP("SD5_LEAD",'Company 2'!$B:$E,4,0),"") -> 0 | AP5: =IFERROR(VLOOKUP("SD6_CONJOINT",'Company 2'!$B:$E,4,0),"") -> 0
B6: Company 3 | C6: =IFERROR(VLOOKUP("Interviewee Position",'Company 3'!$B:$C,2,0),"") -> Business Development / Media Services Manager | D6: =IFERROR(VLOOKUP("Company Industry",'Company 3'!$B:$C,2,0),"") -> B2B Food Service Distribution | E6: =IFERROR(VLOOKUP("Company Sub-Industry",'Company 3'!$B:$C,2,0),"") -> Wholesaler | F6: =IFERROR(VLOOKUP("Company Size (Turnover)",'Company 3'!$B:$C,2,0),"") -> 332000000 | G6: =IFERROR(VLOOKUP("Country",'Company 3'!$B:$C,2,0),"") -> Belgium | H6: =IFERROR(VLOOKUP("B1_INTEREST",'Company 3'!$B:$E,4,0),"") -> 7 | I6: =IFERROR(VLOOKUP("B2_SHARING",'Company 3'!$B:$E,4,0),"") -> 1 | J6: =IFERROR(VLOOKUP("B3_MONETIZE",'Company 3'!$B:$E,4,0),"") -> 1 | K6: =IFERROR(VLOOKUP("B4_STRATEGIC",'Company 3'!$B:$E,4,0),"") -> 1 | L6: =IFERROR(VLOOKUP("M1_AUTOMATED",'Company 3'!$B:$E,4,0),"") -> 4 | M6: =IFERROR(VLOOKUP("M2_REALTIME",'Company 3'!$B:$E,4,0),"") -> 4 | N6: =IFERROR(VLOOKUP("M3_STRATEGIC",'Company 3'!$B:$E,4,0),"") -> 4 | O6: =IFERROR(VLOOKUP("M4_BREADTH",'Company 3'!$B:$E,4,0),"") -> 5 | P6: =IFERROR(VLOOKUP("M5_DATATYPES",'Company 3'!$B:$E,4,0),"") -> 4 | Q6: =IFERROR(VLOOKUP("M6_TRUST",'Company 3'!$B:$E,4,0),"") -> 3 | R6: =IFERROR(VLOOKUP("M7_BARRIERS",'Company 3'!$B:$E,4,0),"") -> 4 | S6: =IFERROR(VLOOKUP("M8_IMPACT",'Company 3'!$B:$E,4,0),"") -> 3 | T6: =IFERROR(VLOOKUP("M9_WILLINGNESS",'Company 3'!$B:$E,4,0),"") -> 8 | U6: =IFERROR(VLOOKUP("SV1_PRICING",'Company 3'!$B:$E,4,0),"") -> 1 | V6: =IFERROR(VLOOKUP("SV2_PROMOTIONS",'Company 3'!$B:$E,4,0),"") -> 1 | W6: =IFERROR(VLOOKUP("SV3_SUPPLYCHAIN",'Company 3'!$B:$E,4,0),"") -> 0 | X6: =IFERROR(VLOOKUP("SV4_CATEGORY",'Company 3'!$B:$E,4,0),"") -> 1 | Y6: =IFERROR(VLOOKUP("SV5_DEMAND",'Company 3'!$B:$E,4,0),"") -> 0 | Z6: =IFERROR(VLOOKUP("SV6_ACCOUNT",'Company 3'!$B:$E,4,0),"") -> 0 | AA6: =IFERROR(VLOOKUP("SV7_OPS",'Company 3'!$B:$E,4,0),"") -> 0 | AB6: =IFERROR(VLOOKUP("SC1_DATASENS",'Company 3'!$B:$E,4,0),"") -> 1 | AC6: =IFERROR(VLOOKUP("SC2_COMPLIANCE",'Company 3'!$B:$E,4,0),"") -> 1 | AD6: =IFERROR(VLOOKUP("SC3_TRUST",'Company 3'!$B:$E,4,0),"") -> 1 | AE6: =IFERROR(VLOOKUP("SC4_DATAPROC",'Company 3'!$B:$E,4,0),"") -> 1 | AF6: =IFERROR(VLOOKUP("SF1_REALTIME",'Company 3'!$B:$E,4,0),"") -> 1 | AG6: =IFERROR(VLOOKUP("SF2_ACCESS",'Company 3'!$B:$E,4,0),"") -> 1 | AH6: =IFERROR(VLOOKUP("SF3_UX",'Company 3'!$B:$E,4,0),"") -> 0 | AI6: =IFERROR(VLOOKUP("SF4_DECISION",'Company 3'!$B:$E,4,0),"") -> 1 | AJ6: =IFERROR(VLOOKUP("SF5_MASKING",'Company 3'!$B:$E,4,0),"") -> 0 | AK6: =IFERROR(VLOOKUP("SD1_TRENDS",'Company 3'!$B:$E,4,0),"") -> 0 | AL6: =IFERROR(VLOOKUP("SD2_MARKET",'Company 3'!$B:$E,4,0),"") -> 0 | AM6: =IFERROR(VLOOKUP("SD3_CATEGORY",'Company 3'!$B:$E,4,0),"") -> 1 | AN6: =IFERROR(VLOOKUP("SD4_SHIPMENT",'Company 3'!$B:$E,4,0),"") -> 0 | AO6: =IFERROR(VLOOKUP("SD5_LEAD",'Company 3'!$B:$E,4,0),"") -> 0 | AP6: =IFERROR(VLOOKUP("SD6_CONJOINT",'Company 3'!$B:$E,4,0),"") -> 0
B7: Company 4 | C7: =IFERROR(VLOOKUP("Interviewee Position",'Company 4'!$B:$C,2,0),"") -> Data/Analytics role (formerly Department Head of Logistics) | D7: =IFERROR(VLOOKUP("Company Industry",'Company 4'!$B:$C,2,0),"") -> Food Service | E7: =IFERROR(VLOOKUP("Company Sub-Industry",'Company 4'!$B:$C,2,0),"") -> Wholesaler | F7: =IFERROR(VLOOKUP("Company Size (Turnover)",'Company 4'!$B:$C,2,0),"") -> 332000000 | G7: =IFERROR(VLOOKUP("Country",'Company 4'!$B:$C,2,0),"") -> Belgium | H7: =IFERROR(VLOOKUP("B1_INTEREST",'Company 4'!$B:$E,4,0),"") -> 7.5 | I7: =IFERROR(VLOOKUP("B2_SHARING",'Company 4'!$B:$E,4,0),"") -> 1 | J7: =IFERROR(VLOOKUP("B3_MONETIZE",'Company 4'!$B:$E,4,0),"") -> 0 | K7: =IFERROR(VLOOKUP("B4_STRATEGIC",'Company 4'!$B:$E,4,0),"") -> 1 | L7: =IFERROR(VLOOKUP("M1_AUTOMATED",'Company 4'!$B:$E,4,0),"") -> 3 | M7: =IFERROR(VLOOKUP("M2_REALTIME",'Company 4'!$B:$E,4,0),"") -> 2 | N7: =IFERROR(VLOOKUP("M3_STRATEGIC",'Company 4'!$B:$E,4,0),"") -> 4 | O7: =IFERROR(VLOOKUP("M4_BREADTH",'Company 4'!$B:$E,4,0),"") -> 2 | P7: =IFERROR(VLOOKUP("M5_DATATYPES",'Company 4'!$B:$E,4,0),"") -> 3 | Q7: =IFERROR(VLOOKUP("M6_TRUST",'Company 4'!$B:$E,4,0),"") -> 2 | R7: =IFERROR(VLOOKUP("M7_BARRIERS",'Company 4'!$B:$E,4,0),"") -> 3 | S7: =IFERROR(VLOOKUP("M8_IMPACT",'Company 4'!$B:$E,4,0),"") -> 0 | T7: =IFERROR(VLOOKUP("M9_WILLINGNESS",'Company 4'!$B:$E,4,0),"") -> 8 | U7: =IFERROR(VLOOKUP("SV1_PRICING",'Company 4'!$B:$E,4,0),"") -> 1 | V7: =IFERROR(VLOOKUP("SV2_PROMOTIONS",'Company 4'!$B:$E,4,0),"") -> 1 | W7: =IFERROR(VLOOKUP("SV3_SUPPLYCHAIN",'Company 4'!$B:$E,4,0),"") -> 1 | X7: =IFERROR(VLOOKUP("SV4_CATEGORY",'Company 4'!$B:$E,4,0),"") -> 1 | Y7: =IFERROR(VLOOKUP("SV5_DEMAND",'Company 4'!$B:$E,4,0),"") -> 0 | Z7: =IFERROR(VLOOKUP("SV6_ACCOUNT",'Company 4'!$B:$E,4,0),"") -> 1 | AA7: =IFERROR(VLOOKUP("SV7_OPS",'Company 4'!$B:$E,4,0),"") -> 1 | AB7: =IFERROR(VLOOKUP("SC1_DATASENS",'Company 4'!$B:$E,4,0),"") -> 1 | AC7: =IFERROR(VLOOKUP("SC2_COMPLIANCE",'Company 4'!$B:$E,4,0),"") -> 1 | AD7: =IFERROR(VLOOKUP("SC3_TRUST",'Company 4'!$B:$E,4,0),"") -> 1 | AE7: =IFERROR(VLOOKUP("SC4_DATAPROC",'Company 4'!$B:$E,4,0),"") -> 1 | AF7: =IFERROR(VLOOKUP("SF1_REALTIME",'Company 4'!$B:$E,4,0),"") -> 0 | AG7: =IFERROR(VLOOKUP("SF2_ACCESS",'Company 4'!$B:$E,4,0),"") -> 0 | AH7: =IFERROR(VLOOKUP("SF3_UX",'Company 4'!$B:$E,4,0),"") -> 1 | AI7: =IFERROR(VLOOKUP("SF4_DECISION",'Company 4'!$B:$E,4,0),"") -> 0 | AJ7: =IFERROR(VLOOKUP("SF5_MASKING",'Company 4'!$B:$E,4,0),"") -> 0 | AK7: =IFERROR(VLOOKUP("SD1_TRENDS",'Company 4'!$B:$E,4,0),"") -> 0 | AL7: =IFERROR(VLOOKUP("SD2_MARKET",'Company 4'!$B:$E,4,0),"") -> 1 | AM7: =IFERROR(VLOOKUP("SD3_CATEGORY",'Company 4'!$B:$E,4,0),"") -> 1 | AN7: =IFERROR(VLOOKUP("SD4_SHIPMENT",'Company 4'!$B:$E,4,0),"") -> 1 | AO7: =IFERROR(VLOOKUP("SD5_LEAD",'Company 4'!$B:$E,4,0),"") -> 1 | AP7: =IFERROR(VLOOKUP("SD6_CONJOINT",'Company 4'!$B:$E,4,0),"") -> 0
B8: Company 5 | C8: =IFERROR(VLOOKUP("Interviewee Position",'Company 5'!$B:$C,2,0),"") -> Supply Chain Director | D8: =IFERROR(VLOOKUP("Company Industry",'Company 5'!$B:$C,2,0),"") -> Food Manufacturing | E8: =IFERROR(VLOOKUP("Company Sub-Industry",'Company 5'!$B:$C,2,0),"") -> Manufacturer | F8: =IFERROR(VLOOKUP("Company Size (Turnover)",'Company 5'!$B:$C,2,0),"") -> 134000000 | G8: =IFERROR(VLOOKUP("Country",'Company 5'!$B:$C,2,0),"") -> Belgium | H8: =IFERROR(VLOOKUP("B1_INTEREST",'Company 5'!$B:$E,4,0),"") -> 10 | I8: =IFERROR(VLOOKUP("B2_SHARING",'Company 5'!$B:$E,4,0),"") -> 1 | J8: =IFERROR(VLOOKUP("B3_MONETIZE",'Company 5'!$B:$E,4,0),"") -> 0 | K8: =IFERROR(VLOOKUP("B4_STRATEGIC",'Company 5'!$B:$E,4,0),"") -> 1 | L8: =IFERROR(VLOOKUP("M1_AUTOMATED",'Company 5'!$B:$E,4,0),"") -> 2 | M8: =IFERROR(VLOOKUP("M2_REALTIME",'Company 5'!$B:$E,4,0),"") -> 2 | N8: =IFERROR(VLOOKUP("M3_STRATEGIC",'Company 5'!$B:$E,4,0),"") -> 2 | O8: =IFERROR(VLOOKUP("M4_BREADTH",'Company 5'!$B:$E,4,0),"") -> 4 | P8: =IFERROR(VLOOKUP("M5_DATATYPES",'Company 5'!$B:$E,4,0),"") -> 2 | Q8: =IFERROR(VLOOKUP("M6_TRUST",'Company 5'!$B:$E,4,0),"") -> 2 | R8: =IFERROR(VLOOKUP("M7_BARRIERS",'Company 5'!$B:$E,4,0),"") -> 4 | S8: =IFERROR(VLOOKUP("M8_IMPACT",'Company 5'!$B:$E,4,0),"") -> 2 | T8: =IFERROR(VLOOKUP("M9_WILLINGNESS",'Company 5'!$B:$E,4,0),"") -> 10 | U8: =IFERROR(VLOOKUP("SV1_PRICING",'Company 5'!$B:$E,4,0),"") -> 1 | V8: =IFERROR(VLOOKUP("SV2_PROMOTIONS",'Company 5'!$B:$E,4,0),"") -> 1 | W8: =IFERROR(VLOOKUP("SV3_SUPPLYCHAIN",'Company 5'!$B:$E,4,0),"") -> 1 | X8: =IFERROR(VLOOKUP("SV4_CATEGORY",'Company 5'!$B:$E,4,0),"") -> 0 | Y8: =IFERROR(VLOOKUP("SV5_DEMAND",'Company 5'!$B:$E,4,0),"") -> 1 | Z8: =IFERROR(VLOOKUP("SV6_ACCOUNT",'Company 5'!$B:$E,4,0),"") -> 1 | AA8: =IFERROR(VLOOKUP("SV7_OPS",'Company 5'!$B:$E,4,0),"") -> 1 | AB8: =IFERROR(VLOOKUP("SC1_DATASENS",'Company 5'!$B:$E,4,0),"") -> 1 | AC8: =IFERROR(VLOOKUP("SC2_COMPLIANCE",'Company 5'!$B:$E,4,0),"") -> 0 | AD8: =IFERROR(VLOOKUP("SC3_TRUST",'Company 5'!$B:$E,4,0),"") -> 1 | AE8: =IFERROR(VLOOKUP("SC4_DATAPROC",'Company 5'!$B:$E,4,0),"") -> 1 | AF8: =IFERROR(VLOOKUP("SF1_REALTIME",'Company 5'!$B:$E,4,0),"") -> 1 | AG8: =IFERROR(VLOOKUP("SF2_ACCESS",'Company 5'!$B:$E,4,0),"") -> 0 | AH8: =IFERROR(VLOOKUP("SF3_UX",'Company 5'!$B:$E,4,0),"") -> 1 | AI8: =IFERROR(VLOOKUP("SF4_DECISION",'Company 5'!$B:$E,4,0),"") -> 1 | AJ8: =IFERROR(VLOOKUP("SF5_MASKING",'Company 5'!$B:$E,4,0),"") -> 0 | AK8: =IFERROR(VLOOKUP("SD1_TRENDS",'Company 5'!$B:$E,4,0),"") -> 0 | AL8: =IFERROR(VLOOKUP("SD2_MARKET",'Company 5'!$B:$E,4,0),"") -> 0 | AM8: =IFERROR(VLOOKUP("SD3_CATEGORY",'Company 5'!$B:$E,4,0),"") -> 0 | AN8: =IFERROR(VLOOKUP("SD4_SHIPMENT",'Company 5'!$B:$E,4,0),"") -> 1 | AO8: =IFERROR(VLOOKUP("SD5_LEAD",'Company 5'!$B:$E,4,0),"") -> 1 | AP8: =IFERROR(VLOOKUP("SD6_CONJOINT",'Company 5'!$B:$E,4,0),"") -> 0
B9: Company 6 | C9: =IFERROR(VLOOKUP("Interviewee Position",'Company 6'!$B:$C,2,0),"") -> Sales Director | D9: =IFERROR(VLOOKUP("Company Industry",'Company 6'!$B:$C,2,0),"") -> FMCG | E9: =IFERROR(VLOOKUP("Company Sub-Industry",'Company 6'!$B:$C,2,0),"") -> Manufacturer | F9: =IFERROR(VLOOKUP("Company Size (Turnover)",'Company 6'!$B:$C,2,0),"") -> 380000000 | G9: =IFERROR(VLOOKUP("Country",'Company 6'!$B:$C,2,0),"") -> Belgium | H9: =IFERROR(VLOOKUP("B1_INTEREST",'Company 6'!$B:$E,4,0),"") -> 8 | I9: =IFERROR(VLOOKUP("B2_SHARING",'Company 6'!$B:$E,4,0),"") -> 1 | J9: =IFERROR(VLOOKUP("B3_MONETIZE",'Company 6'!$B:$E,4,0),"") -> 0 | K9: =IFERROR(VLOOKUP("B4_STRATEGIC",'Company 6'!$B:$E,4,0),"") -> 1 | L9: =IFERROR(VLOOKUP("M1_AUTOMATED",'Company 6'!$B:$E,4,0),"") -> 5 | M9: =IFERROR(VLOOKUP("M2_REALTIME",'Company 6'!$B:$E,4,0),"") -> 4 | N9: =IFERROR(VLOOKUP("M3_STRATEGIC",'Company 6'!$B:$E,4,0),"") -> 4 | O9: =IFERROR(VLOOKUP("M4_BREADTH",'Company 6'!$B:$E,4,0),"") -> 3 | P9: =IFERROR(VLOOKUP("M5_DATATYPES",'Company 6'!$B:$E,4,0),"") -> 5 | Q9: =IFERROR(VLOOKUP("M6_TRUST",'Company 6'!$B:$E,4,0),"") -> 2 | R9: =IFERROR(VLOOKUP("M7_BARRIERS",'Company 6'!$B:$E,4,0),"") -> 5 | S9: =IFERROR(VLOOKUP("M8_IMPACT",'Company 6'!$B:$E,4,0),"") -> 5 | T9: =IFERROR(VLOOKUP("M9_WILLINGNESS",'Company 6'!$B:$E,4,0),"") -> 6 | U9: =IFERROR(VLOOKUP("SV1_PRICING",'Company 6'!$B:$E,4,0),"") -> 1 | V9: =IFERROR(VLOOKUP("SV2_PROMOTIONS",'Company 6'!$B:$E,4,0),"") -> 1 | W9: =IFERROR(VLOOKUP("SV3_SUPPLYCHAIN",'Company 6'!$B:$E,4,0),"") -> 1 | X9: =IFERROR(VLOOKUP("SV4_CATEGORY",'Company 6'!$B:$E,4,0),"") -> 1 | Y9: =IFERROR(VLOOKUP("SV5_DEMAND",'Company 6'!$B:$E,4,0),"") -> 1 | Z9: =IFERROR(VLOOKUP("SV6_ACCOUNT",'Company 6'!$B:$E,4,0),"") -> 1 | AA9: =IFERROR(VLOOKUP("SV7_OPS",'Company 6'!$B:$E,4,0),"") -> 1 | AB9: =IFERROR(VLOOKUP("SC1_DATASENS",'Company 6'!$B:$E,4,0),"") -> 1 | AC9: =IFERROR(VLOOKUP("SC2_COMPLIANCE",'Company 6'!$B:$E,4,0),"") -> 1 | AD9: =IFERROR(VLOOKUP("SC3_TRUST",'Company 6'!$B:$E,4,0),"") -> 1 | AE9: =IFERROR(VLOOKUP("SC4_DATAPROC",'Company 6'!$B:$E,4,0),"") -> 1 | AF9: =IFERROR(VLOOKUP("SF1_REALTIME",'Company 6'!$B:$E,4,0),"") -> 1 | AG9: =IFERROR(VLOOKUP("SF2_ACCESS",'Company 6'!$B:$E,4,0),"") -> 1 | AH9: =IFERROR(VLOOKUP("SF3_UX",'Company 6'!$B:$E,4,0),"") -> 0 | AI9: =IFERROR(VLOOKUP("SF4_DECISION",'Company 6'!$B:$E,4,0),"") -> 1 | AJ9: =IFERROR(VLOOKUP("SF5_MASKING",'Company 6'!$B:$E,4,0),"") -> 0 | AK9: =IFERROR(VLOOKUP("SD1_TRENDS",'Company 6'!$B:$E,4,0),"") -> 1 | AL9: =IFERROR(VLOOKUP("SD2_MARKET",'Company 6'!$B:$E,4,0),"") -> 1 | AM9: =IFERROR(VLOOKUP("SD3_CATEGORY",'Company 6'!$B:$E,4,0),"") -> 1 | AN9: =IFERROR(VLOOKUP("SD4_SHIPMENT",'Company 6'!$B:$E,4,0),"") -> 1 | AO9: =IFERROR(VLOOKUP("SD5_LEAD",'Company 6'!$B:$E,4,0),"") -> 0 | AP9: =IFERROR(VLOOKUP("SD6_CONJOINT",'Company 6'!$B:$E,4,0),"") -> 0
B10: Company 7 | C10: =IFERROR(VLOOKUP("Interviewee Position",'Company 7'!$B:$C,2,0),"") -> CEO | D10: =IFERROR(VLOOKUP("Company Industry",'Company 7'!$B:$C,2,0),"") -> Food Service / Wholesale Distribution | E10: =IFERROR(VLOOKUP("Company Sub-Industry",'Company 7'!$B:$C,2,0),"") -> Wholesaler | F10: =IFERROR(VLOOKUP("Company Size (Turnover)",'Company 7'!$B:$C,2,0),"") -> 7800000 | G10: =IFERROR(VLOOKUP("Country",'Company 7'!$B:$C,2,0),"") -> Belgium | H10: =IFERROR(VLOOKUP("B1_INTEREST",'Company 7'!$B:$E,4,0),"") -> 8 | I10: =IFERROR(VLOOKUP("B2_SHARING",'Company 7'!$B:$E,4,0),"") -> 1 | J10: =IFERROR(VLOOKUP("B3_MONETIZE",'Company 7'!$B:$E,4,0),"") -> 1 | K10: =IFERROR(VLOOKUP("B4_STRATEGIC",'Company 7'!$B:$E,4,0),"") -> 0 | L10: =IFERROR(VLOOKUP("M1_AUTOMATED",'Company 7'!$B:$E,4,0),"") -> 1 | M10: =IFERROR(VLOOKUP("M2_REALTIME",'Company 7'!$B:$E,4,0),"") -> 2 | N10: =IFERROR(VLOOKUP("M3_STRATEGIC",'Company 7'!$B:$E,4,0),"") -> 4 | O10: =IFERROR(VLOOKUP("M4_BREADTH",'Company 7'!$B:$E,4,0),"") -> 3 | P10: =IFERROR(VLOOKUP("M5_DATATYPES",'Company 7'!$B:$E,4,0),"") -> 3 | Q10: =IFERROR(VLOOKUP("M6_TRUST",'Company 7'!$B:$E,4,0),"") -> 0 | R10: =IFERROR(VLOOKUP("M7_BARRIERS",'Company 7'!$B:$E,4,0),"") -> 2 | S10: =IFERROR(VLOOKUP("M8_IMPACT",'Company 7'!$B:$E,4,0),"") -> 3 | T10: =IFERROR(VLOOKUP("M9_WILLINGNESS",'Company 7'!$B:$E,4,0),"") -> 8 | U10: =IFERROR(VLOOKUP("SV1_PRICING",'Company 7'!$B:$E,4,0),"") -> 0 | V10: =IFERROR(VLOOKUP("SV2_PROMOTIONS",'Company 7'!$B:$E,4,0),"") -> 0 | W10: =IFERROR(VLOOKUP("SV3_SUPPLYCHAIN",'Company 7'!$B:$E,4,0),"") -> 0 | X10: =IFERROR(VLOOKUP("SV4_CATEGORY",'Company 7'!$B:$E,4,0),"") -> 1 | Y10: =IFERROR(VLOOKUP("SV5_DEMAND",'Company 7'!$B:$E,4,0),"") -> 0 | Z10: =IFERROR(VLOOKUP("SV6_ACCOUNT",'Company 7'!$B:$E,4,0),"") -> 0 | AA10: =IFERROR(VLOOKUP("SV7_OPS",'Company 7'!$B:$E,4,0),"") -> 1 | AB10: =IFERROR(VLOOKUP("SC1_DATASENS",'Company 7'!$B:$E,4,0),"") -> 0 | AC10: =IFERROR(VLOOKUP("SC2_COMPLIANCE",'Company 7'!$B:$E,4,0),"") -> 0 | AD10: =IFERROR(VLOOKUP("SC3_TRUST",'Company 7'!$B:$E,4,0),"") -> 0 | AE10: =IFERROR(VLOOKUP("SC4_DATAPROC",'Company 7'!$B:$E,4,0),"") -> 1 | AF10: =IFERROR(VLOOKUP("SF1_REALTIME",'Company 7'!$B:$E,4,0),"") -> 1 | AG10: =IFERROR(VLOOKUP("SF2_ACCESS",'Company 7'!$B:$E,4,0),"") -> 0 | AH10: =IFERROR(VLOOKUP("SF3_UX",'Company 7'!$B:$E,4,0),"") -> 1 | AI10: =IFERROR(VLOOKUP("SF4_DECISION",'Company 7'!$B:$E,4,0),"") -> 0 | AJ10: =IFERROR(VLOOKUP("SF5_MASKING",'Company 7'!$B:$E,4,0),"") -> 0 | AK10: =IFERROR(VLOOKUP("SD1_TRENDS",'Company 7'!$B:$E,4,0),"") -> 0 | AL10: =IFERROR(VLOOKUP("SD2_MARKET",'Company 7'!$B:$E,4,0),"") -> 1 | AM10: =IFERROR(VLOOKUP("SD3_CATEGORY",'Company 7'!$B:$E,4,0),"") -> 1 | AN10: =IFERROR(VLOOKUP("SD4_SHIPMENT",'Company 7'!$B:$E,4,0),"") -> 0 | AO10: =IFERROR(VLOOKUP("SD5_LEAD",'Company 7'!$B:$E,4,0),"") -> 0 | AP10: =IFERROR(VLOOKUP("SD6_CONJOINT",'Company 7'!$B:$E,4,0),"") -> 0
B11: Company 8 | C11: =IFERROR(VLOOKUP("Interviewee Position",'Company 8'!$B:$C,2,0),"") -> CFO / Finance Lead EMEA & LATAM | D11: =IFERROR(VLOOKUP("Company Industry",'Company 8'!$B:$C,2,0),"") -> Pet Food & Products | E11: =IFERROR(VLOOKUP("Company Sub-Industry",'Company 8'!$B:$C,2,0),"") -> Manufacturer | F11: =IFERROR(VLOOKUP("Company Size (Turnover)",'Company 8'!$B:$C,2,0),"") -> 90000000 | G11: =IFERROR(VLOOKUP("Country",'Company 8'!$B:$C,2,0),"") -> US | H11: =IFERROR(VLOOKUP("B1_INTEREST",'Company 8'!$B:$E,4,0),"") -> 8 | I11: =IFERROR(VLOOKUP("B2_SHARING",'Company 8'!$B:$E,4,0),"") -> 1 | J11: =IFERROR(VLOOKUP("B3_MONETIZE",'Company 8'!$B:$E,4,0),"") -> 0 | K11: =IFERROR(VLOOKUP("B4_STRATEGIC",'Company 8'!$B:$E,4,0),"") -> 0 | L11: =IFERROR(VLOOKUP("M1_AUTOMATED",'Company 8'!$B:$E,4,0),"") -> 3 | M11: =IFERROR(VLOOKUP("M2_REALTIME",'Company 8'!$B:$E,4,0),"") -> 2 | N11: =IFERROR(VLOOKUP("M3_STRATEGIC",'Company 8'!$B:$E,4,0),"") -> 4 | O11: =IFERROR(VLOOKUP("M4_BREADTH",'Company 8'!$B:$E,4,0),"") -> 3 | P11: =IFERROR(VLOOKUP("M5_DATATYPES",'Company 8'!$B:$E,4,0),"") -> 4 | Q11: =IFERROR(VLOOKUP("M6_TRUST",'Company 8'!$B:$E,4,0),"") -> 4 | R11: =IFERROR(VLOOKUP("M7_BARRIERS",'Company 8'!$B:$E,4,0),"") -> 4 | S11: =IFERROR(VLOOKUP("M8_IMPACT",'Company 8'!$B:$E,4,0),"") -> 2 | T11: =IFERROR(VLOOKUP("M9_WILLINGNESS",'Company 8'!$B:$E,4,0),"") -> 8 | U11: =IFERROR(VLOOKUP("SV1_PRICING",'Company 8'!$B:$E,4,0),"") -> 1 | V11: =IFERROR(VLOOKUP("SV2_PROMOTIONS",'Company 8'!$B:$E,4,0),"") -> 1 | W11: =IFERROR(VLOOKUP("SV3_SUPPLYCHAIN",'Company 8'!$B:$E,4,0),"") -> 0 | X11: =IFERROR(VLOOKUP("SV4_CATEGORY",'Company 8'!$B:$E,4,0),"") -> 1 | Y11: =IFERROR(VLOOKUP("SV5_DEMAND",'Company 8'!$B:$E,4,0),"") -> 0 | Z11: =IFERROR(VLOOKUP("SV6_ACCOUNT",'Company 8'!$B:$E,4,0),"") -> 0 | AA11: =IFERROR(VLOOKUP("SV7_OPS",'Company 8'!$B:$E,4,0),"") -> 0 | AB11: =IFERROR(VLOOKUP("SC1_DATASENS",'Company 8'!$B:$E,4,0),"") -> 1 | AC11: =IFERROR(VLOOKUP("SC2_COMPLIANCE",'Company 8'!$B:$E,4,0),"") -> 1 | AD11: =IFERROR(VLOOKUP("SC3_TRUST",'Company 8'!$B:$E,4,0),"") -> 0 | AE11: =IFERROR(VLOOKUP("SC4_DATAPROC",'Company 8'!$B:$E,4,0),"") -> 0 | AF11: =IFERROR(VLOOKUP("SF1_REALTIME",'Company 8'!$B:$E,4,0),"") -> 0 | AG11: =IFERROR(VLOOKUP("SF2_ACCESS",'Company 8'!$B:$E,4,0),"") -> 0 | AH11: =IFERROR(VLOOKUP("SF3_UX",'Company 8'!$B:$E,4,0),"") -> 0 | AI11: =IFERROR(VLOOKUP("SF4_DECISION",'Company 8'!$B:$E,4,0),"") -> 0 | AJ11: =IFERROR(VLOOKUP("SF5_MASKING",'Company 8'!$B:$E,4,0),"") -> 0 | AK11: =IFERROR(VLOOKUP("SD1_TRENDS",'Company 8'!$B:$E,4,0),"") -> 1 | AL11: =IFERROR(VLOOKUP("SD2_MARKET",'Company 8'!$B:$E,4,0),"") -> 1 | AM11: =IFERROR(VLOOKUP("SD3_CATEGORY",'Company 8'!$B:$E,4,0),"") -> 1 | AN11: =IFERROR(VLOOKUP("SD4_SHIPMENT",'Company 8'!$B:$E,4,0),"") -> 0 | AO11: =IFERROR(VLOOKUP("SD5_LEAD",'Company 8'!$B:$E,4,0),"") -> 0 | AP11: =IFERROR(VLOOKUP("SD6_CONJOINT",'Company 8'!$B:$E,4,0),"") -> 0
B12: Company 9 | C12: =IFERROR(VLOOKUP("Interviewee Position",'Company 9'!$B:$C,2,0),"") -> Commercial Director | D12: =IFERROR(VLOOKUP("Company Industry",'Company 9'!$B:$C,2,0),"") -> Wholesale | E12: =IFERROR(VLOOKUP("Company Sub-Industry",'Company 9'!$B:$C,2,0),"") -> Wholesaler | F12: =IFERROR(VLOOKUP("Company Size (Turnover)",'Company 9'!$B:$C,2,0),"") -> 2000000000 | G12: =IFERROR(VLOOKUP("Country",'Company 9'!$B:$C,2,0),"") -> Belgium | H12: =IFERROR(VLOOKUP("B1_INTEREST",'Company 9'!$B:$E,4,0),"") -> 8 | I12: =IFERROR(VLOOKUP("B2_SHARING",'Company 9'!$B:$E,4,0),"") -> 1 | J12: =IFERROR(VLOOKUP("B3_MONETIZE",'Company 9'!$B:$E,4,0),"") -> 1 | K12: =IFERROR(VLOOKUP("B4_STRATEGIC",'Company 9'!$B:$E,4,0),"") -> 0 | L12: =IFERROR(VLOOKUP("M1_AUTOMATED",'Company 9'!$B:$E,4,0),"") -> 3 | M12: =IFERROR(VLOOKUP("M2_REALTIME",'Company 9'!$B:$E,4,0),"") -> 2 | N12: =IFERROR(VLOOKUP("M3_STRATEGIC",'Company 9'!$B:$E,4,0),"") -> 4 | O12: =IFERROR(VLOOKUP("M4_BREADTH",'Company 9'!$B:$E,4,0),"") -> 2 | P12: =IFERROR(VLOOKUP("M5_DATATYPES",'Company 9'!$B:$E,4,0),"") -> 5 | Q12: =IFERROR(VLOOKUP("M6_TRUST",'Company 9'!$B:$E,4,0),"") -> 2 | R12: =IFERROR(VLOOKUP("M7_BARRIERS",'Company 9'!$B:$E,4,0),"") -> 4 | S12: =IFERROR(VLOOKUP("M8_IMPACT",'Company 9'!$B:$E,4,0),"") -> 4 | T12: =IFERROR(VLOOKUP("M9_WILLINGNESS",'Company 9'!$B:$E,4,0),"") -> 6 | U12: =IFERROR(VLOOKUP("SV1_PRICING",'Company 9'!$B:$E,4,0),"") -> 0 | V12: =IFERROR(VLOOKUP("SV2_PROMOTIONS",'Company 9'!$B:$E,4,0),"") -> 0 | W12: =IFERROR(VLOOKUP("SV3_SUPPLYCHAIN",'Company 9'!$B:$E,4,0),"") -> 0 | X12: =IFERROR(VLOOKUP("SV4_CATEGORY",'Company 9'!$B:$E,4,0),"") -> 1 | Y12: =IFERROR(VLOOKUP("SV5_DEMAND",'Company 9'!$B:$E,4,0),"") -> 1 | Z12: =IFERROR(VLOOKUP("SV6_ACCOUNT",'Company 9'!$B:$E,4,0),"") -> 0 | AA12: =IFERROR(VLOOKUP("SV7_OPS",'Company 9'!$B:$E,4,0),"") -> 0 | AB12: =IFERROR(VLOOKUP("SC1_DATASENS",'Company 9'!$B:$E,4,0),"") -> 1 | AC12: =IFERROR(VLOOKUP("SC2_COMPLIANCE",'Company 9'!$B:$E,4,0),"") -> 0 | AD12: =IFERROR(VLOOKUP("SC3_TRUST",'Company 9'!$B:$E,4,0),"") -> 0 | AE12: =IFERROR(VLOOKUP("SC4_DATAPROC",'Company 9'!$B:$E,4,0),"") -> 0 | AF12: =IFERROR(VLOOKUP("SF1_REALTIME",'Company 9'!$B:$E,4,0),"") -> 0 | AG12: =IFERROR(VLOOKUP("SF2_ACCESS",'Company 9'!$B:$E,4,0),"") -> 1 | AH12: =IFERROR(VLOOKUP("SF3_UX",'Company 9'!$B:$E,4,0),"") -> 1 | AI12: =IFERROR(VLOOKUP("SF4_DECISION",'Company 9'!$B:$E,4,0),"") -> 0 | AJ12: =IFERROR(VLOOKUP("SF5_MASKING",'Company 9'!$B:$E,4,0),"") -> 0 | AK12: =IFERROR(VLOOKUP("SD1_TRENDS",'Company 9'!$B:$E,4,0),"") -> 1 | AL12: =IFERROR(VLOOKUP("SD2_MARKET",'Company 9'!$B:$E,4,0),"") -> 1 | AM12: =IFERROR(VLOOKUP("SD3_CATEGORY",'Company 9'!$B:$E,4,0),"") -> 1 | AN12: =IFERROR(VLOOKUP("SD4_SHIPMENT",'Company 9'!$B:$E,4,0),"") -> 1 | AO12: =IFERROR(VLOOKUP("SD5_LEAD",'Company 9'!$B:$E,4,0),"") -> 0 | AP12: =IFERROR(VLOOKUP("SD6_CONJOINT",'Company 9'!$B:$E,4,0),"") -> 0
B13: Company 10 | C13: =IFERROR(VLOOKUP("Interviewee Position",'Company 10'!$B:$C,2,0),"") -> Data Insights Team | D13: =IFERROR(VLOOKUP("Company Industry",'Company 10'!$B:$C,2,0),"") -> FMCG | E13: =IFERROR(VLOOKUP("Company Sub-Industry",'Company 10'!$B:$C,2,0),"") -> Manufacturer | F13: =IFERROR(VLOOKUP("Company Size (Turnover)",'Company 10'!$B:$C,2,0),"") -> 52000000 | G13: =IFERROR(VLOOKUP("Country",'Company 10'!$B:$C,2,0),"") -> Denmark | H13: =IFERROR(VLOOKUP("B1_INTEREST",'Company 10'!$B:$E,4,0),"") -> 7 | I13: =IFERROR(VLOOKUP("B2_SHARING",'Company 10'!$B:$E,4,0),"") -> 1 | J13: =IFERROR(VLOOKUP("B3_MONETIZE",'Company 10'!$B:$E,4,0),"") -> 0 | K13: =IFERROR(VLOOKUP("B4_STRATEGIC",'Company 10'!$B:$E,4,0),"") -> 1 | L13: =IFERROR(VLOOKUP("M1_AUTOMATED",'Company 10'!$B:$E,4,0),"") -> 2 | M13: =IFERROR(VLOOKUP("M2_REALTIME",'Company 10'!$B:$E,4,0),"") -> 2 | N13: =IFERROR(VLOOKUP("M3_STRATEGIC",'Company 10'!$B:$E,4,0),"") -> 5 | O13: =IFERROR(VLOOKUP("M4_BREADTH",'Company 10'!$B:$E,4,0),"") -> 3 | P13: =IFERROR(VLOOKUP("M5_DATATYPES",'Company 10'!$B:$E,4,0),"") -> 5 | Q13: =IFERROR(VLOOKUP("M6_TRUST",'Company 10'!$B:$E,4,0),"") -> 3 | R13: =IFERROR(VLOOKUP("M7_BARRIERS",'Company 10'!$B:$E,4,0),"") -> 4 | S13: =IFERROR(VLOOKUP("M8_IMPACT",'Company 10'!$B:$E,4,0),"") -> 4 | T13: =IFERROR(VLOOKUP("M9_WILLINGNESS",'Company 10'!$B:$E,4,0),"") -> 7 | U13: =IFERROR(VLOOKUP("SV1_PRICING",'Company 10'!$B:$E,4,0),"") -> 1 | V13: =IFERROR(VLOOKUP("SV2_PROMOTIONS",'Company 10'!$B:$E,4,0),"") -> 0 | W13: =IFERROR(VLOOKUP("SV3_SUPPLYCHAIN",'Company 10'!$B:$E,4,0),"") -> 1 | X13: =IFERROR(VLOOKUP("SV4_CATEGORY",'Company 10'!$B:$E,4,0),"") -> 1 | Y13: =IFERROR(VLOOKUP("SV5_DEMAND",'Company 10'!$B:$E,4,0),"") -> 0 | Z13: =IFERROR(VLOOKUP("SV6_ACCOUNT",'Company 10'!$B:$E,4,0),"") -> 0 | AA13: =IFERROR(VLOOKUP("SV7_OPS",'Company 10'!$B:$E,4,0),"") -> 0 | AB13: =IFERROR(VLOOKUP("SC1_DATASENS",'Company 10'!$B:$E,4,0),"") -> 1 | AC13: =IFERROR(VLOOKUP("SC2_COMPLIANCE",'Company 10'!$B:$E,4,0),"") -> 1 | AD13: =IFERROR(VLOOKUP("SC3_TRUST",'Company 10'!$B:$E,4,0),"") -> 0 | AE13: =IFERROR(VLOOKUP("SC4_DATAPROC",'Company 10'!$B:$E,4,0),"") -> 1 | AF13: =IFERROR(VLOOKUP("SF1_REALTIME",'Company 10'!$B:$E,4,0),"") -> 1 | AG13: =IFERROR(VLOOKUP("SF2_ACCESS",'Company 10'!$B:$E,4,0),"") -> 0 | AH13: =IFERROR(VLOOKUP("SF3_UX",'Company 10'!$B:$E,4,0),"") -> 1 | AI13: =IFERROR(VLOOKUP("SF4_DECISION",'Company 10'!$B:$E,4,0),"") -> 0 | AJ13: =IFERROR(VLOOKUP("SF5_MASKING",'Company 10'!$B:$E,4,0),"") -> 0 | AK13: =IFERROR(VLOOKUP("SD1_TRENDS",'Company 10'!$B:$E,4,0),"") -> 1 | AL13: =IFERROR(VLOOKUP("SD2_MARKET",'Company 10'!$B:$E,4,0),"") -> 1 | AM13: =IFERROR(VLOOKUP("SD3_CATEGORY",'Company 10'!$B:$E,4,0),"") -> 1 | AN13: =IFERROR(VLOOKUP("SD4_SHIPMENT",'Company 10'!$B:$E,4,0),"") -> 0 | AO13: =IFERROR(VLOOKUP("SD5_LEAD",'Company 10'!$B:$E,4,0),"") -> 0 | AP13: =IFERROR(VLOOKUP("SD6_CONJOINT",'Company 10'!$B:$E,4,0),"") -> 0
B14: Company 11 | C14: =IFERROR(VLOOKUP("Interviewee Position",'Company 11'!$B:$C,2,0),"") -> Marketing Strategic Role | D14: =IFERROR(VLOOKUP("Company Industry",'Company 11'!$B:$C,2,0),"") -> Pharmacy/Healthcare Retail | E14: =IFERROR(VLOOKUP("Company Sub-Industry",'Company 11'!$B:$C,2,0),"") -> Specialty Retail | F14: =IFERROR(VLOOKUP("Company Size (Turnover)",'Company 11'!$B:$C,2,0),"") -> 140000000 | G14: =IFERROR(VLOOKUP("Country",'Company 11'!$B:$C,2,0),"") -> Belgium | H14: =IFERROR(VLOOKUP("B1_INTEREST",'Company 11'!$B:$E,4,0),"") -> 9 | I14: =IFERROR(VLOOKUP("B2_SHARING",'Company 11'!$B:$E,4,0),"") -> 1 | J14: =IFERROR(VLOOKUP("B3_MONETIZE",'Company 11'!$B:$E,4,0),"") -> 0 | K14: =IFERROR(VLOOKUP("B4_STRATEGIC",'Company 11'!$B:$E,4,0),"") -> 0 | L14: =IFERROR(VLOOKUP("M1_AUTOMATED",'Company 11'!$B:$E,4,0),"") -> 1 | M14: =IFERROR(VLOOKUP("M2_REALTIME",'Company 11'!$B:$E,4,0),"") -> 1 | N14: =IFERROR(VLOOKUP("M3_STRATEGIC",'Company 11'!$B:$E,4,0),"") -> 2 | O14: =IFERROR(VLOOKUP("M4_BREADTH",'Company 11'!$B:$E,4,0),"") -> 2 | P14: =IFERROR(VLOOKUP("M5_DATATYPES",'Company 11'!$B:$E,4,0),"") -> 2 | Q14: =IFERROR(VLOOKUP("M6_TRUST",'Company 11'!$B:$E,4,0),"") -> 0 | R14: =IFERROR(VLOOKUP("M7_BARRIERS",'Company 11'!$B:$E,4,0),"") -> 2 | S14: =IFERROR(VLOOKUP("M8_IMPACT",'Company 11'!$B:$E,4,0),"") -> 0 | T14: =IFERROR(VLOOKUP("M9_WILLINGNESS",'Company 11'!$B:$E,4,0),"") -> 9 | U14: =IFERROR(VLOOKUP("SV1_PRICING",'Company 11'!$B:$E,4,0),"") -> 1 | V14: =IFERROR(VLOOKUP("SV2_PROMOTIONS",'Company 11'!$B:$E,4,0),"") -> 1 | W14: =IFERROR(VLOOKUP("SV3_SUPPLYCHAIN",'Company 11'!$B:$E,4,0),"") -> 1 | X14: =IFERROR(VLOOKUP("SV4_CATEGORY",'Company 11'!$B:$E,4,0),"") -> 1 | Y14: =IFERROR(VLOOKUP("SV5_DEMAND",'Company 11'!$B:$E,4,0),"") -> 0 | Z14: =IFERROR(VLOOKUP("SV6_ACCOUNT",'Company 11'!$B:$E,4,0),"") -> 0 | AA14: =IFERROR(VLOOKUP("SV7_OPS",'Company 11'!$B:$E,4,0),"") -> 0 | AB14: =IFERROR(VLOOKUP("SC1_DATASENS",'Company 11'!$B:$E,4,0),"") -> 1 | AC14: =IFERROR(VLOOKUP("SC2_COMPLIANCE",'Company 11'!$B:$E,4,0),"") -> 0 | AD14: =IFERROR(VLOOKUP("SC3_TRUST",'Company 11'!$B:$E,4,0),"") -> 0 | AE14: =IFERROR(VLOOKUP("SC4_DATAPROC",'Company 11'!$B:$E,4,0),"") -> 1 | AF14: =IFERROR(VLOOKUP("SF1_REALTIME",'Company 11'!$B:$E,4,0),"") -> 0 | AG14: =IFERROR(VLOOKUP("SF2_ACCESS",'Company 11'!$B:$E,4,0),"") -> 0 | AH14: =IFERROR(VLOOKUP("SF3_UX",'Company 11'!$B:$E,4,0),"") -> 1 | AI14: =IFERROR(VLOOKUP("SF4_DECISION",'Company 11'!$B:$E,4,0),"") -> 0 | AJ14: =IFERROR(VLOOKUP("SF5_MASKING",'Company 11'!$B:$E,4,0),"") -> 0 | AK14: =IFERROR(VLOOKUP("SD1_TRENDS",'Company 11'!$B:$E,4,0),"") -> 1 | AL14: =IFERROR(VLOOKUP("SD2_MARKET",'Company 11'!$B:$E,4,0),"") -> 1 | AM14: =IFERROR(VLOOKUP("SD3_CATEGORY",'Company 11'!$B:$E,4,0),"") -> 1 | AN14: =IFERROR(VLOOKUP("SD4_SHIPMENT",'Company 11'!$B:$E,4,0),"") -> 0 | AO14: =IFERROR(VLOOKUP("SD5_LEAD",'Company 11'!$B:$E,4,0),"") -> 0 | AP14: =IFERROR(VLOOKUP("SD6_CONJOINT",'Company 11'!$B:$E,4,0),"") -> 0
B15: Company 12 | C15: =IFERROR(VLOOKUP("Interviewee Position",'Company 12'!$B:$C,2,0),"") -> Marketing / Commercial Director | D15: =IFERROR(VLOOKUP("Company Industry",'Company 12'!$B:$C,2,0),"") -> Grocery Retail | E15: =IFERROR(VLOOKUP("Company Sub-Industry",'Company 12'!$B:$C,2,0),"") -> Retailer | F15: =IFERROR(VLOOKUP("Company Size (Turnover)",'Company 12'!$B:$C,2,0),"") -> 3240000000 | G15: =IFERROR(VLOOKUP("Country",'Company 12'!$B:$C,2,0),"") -> Germany | H15: =IFERROR(VLOOKUP("B1_INTEREST",'Company 12'!$B:$E,4,0),"") -> 3 | I15: =IFERROR(VLOOKUP("B2_SHARING",'Company 12'!$B:$E,4,0),"") -> 1 | J15: =IFERROR(VLOOKUP("B3_MONETIZE",'Company 12'!$B:$E,4,0),"") -> 0 | K15: =IFERROR(VLOOKUP("B4_STRATEGIC",'Company 12'!$B:$E,4,0),"") -> 1 | L15: =IFERROR(VLOOKUP("M1_AUTOMATED",'Company 12'!$B:$E,4,0),"") -> 0 | M15: =IFERROR(VLOOKUP("M2_REALTIME",'Company 12'!$B:$E,4,0),"") -> 0 | N15: =IFERROR(VLOOKUP("M3_STRATEGIC",'Company 12'!$B:$E,4,0),"") -> 2 | O15: =IFERROR(VLOOKUP("M4_BREADTH",'Company 12'!$B:$E,4,0),"") -> 1 | P15: =IFERROR(VLOOKUP("M5_DATATYPES",'Company 12'!$B:$E,4,0),"") -> 2 | Q15: =IFERROR(VLOOKUP("M6_TRUST",'Company 12'!$B:$E,4,0),"") -> 0 | R15: =IFERROR(VLOOKUP("M7_BARRIERS",'Company 12'!$B:$E,4,0),"") -> 4 | S15: =IFERROR(VLOOKUP("M8_IMPACT",'Company 12'!$B:$E,4,0),"") -> 4 | T15: =IFERROR(VLOOKUP("M9_WILLINGNESS",'Company 12'!$B:$E,4,0),"") -> 3 | U15: =IFERROR(VLOOKUP("SV1_PRICING",'Company 12'!$B:$E,4,0),"") -> 0 | V15: =IFERROR(VLOOKUP("SV2_PROMOTIONS",'Company 12'!$B:$E,4,0),"") -> 1 | W15: =IFERROR(VLOOKUP("SV3_SUPPLYCHAIN",'Company 12'!$B:$E,4,0),"") -> 1 | X15: =IFERROR(VLOOKUP("SV4_CATEGORY",'Company 12'!$B:$E,4,0),"") -> 0 | Y15: =IFERROR(VLOOKUP("SV5_DEMAND",'Company 12'!$B:$E,4,0),"") -> 1 | Z15: =IFERROR(VLOOKUP("SV6_ACCOUNT",'Company 12'!$B:$E,4,0),"") -> 0 | AA15: =IFERROR(VLOOKUP("SV7_OPS",'Company 12'!$B:$E,4,0),"") -> 0 | AB15: =IFERROR(VLOOKUP("SC1_DATASENS",'Company 12'!$B:$E,4,0),"") -> 1 | AC15: =IFERROR(VLOOKUP("SC2_COMPLIANCE",'Company 12'!$B:$E,4,0),"") -> 1 | AD15: =IFERROR(VLOOKUP("SC3_TRUST",'Company 12'!$B:$E,4,0),"") -> 0 | AE15: =IFERROR(VLOOKUP("SC4_DATAPROC",'Company 12'!$B:$E,4,0),"") -> 0 | AF15: =IFERROR(VLOOKUP("SF1_REALTIME",'Company 12'!$B:$E,4,0),"") -> 0 | AG15: =IFERROR(VLOOKUP("SF2_ACCESS",'Company 12'!$B:$E,4,0),"") -> 0 | AH15: =IFERROR(VLOOKUP("SF3_UX",'Company 12'!$B:$E,4,0),"") -> 0 | AI15: =IFERROR(VLOOKUP("SF4_DECISION",'Company 12'!$B:$E,4,0),"") -> 0 | AJ15: =IFERROR(VLOOKUP("SF5_MASKING",'Company 12'!$B:$E,4,0),"") -> 1 | AK15: =IFERROR(VLOOKUP("SD1_TRENDS",'Company 12'!$B:$E,4,0),"") -> 1 | AL15: =IFERROR(VLOOKUP("SD2_MARKET",'Company 12'!$B:$E,4,0),"") -> 1 | AM15: =IFERROR(VLOOKUP("SD3_CATEGORY",'Company 12'!$B:$E,4,0),"") -> 0 | AN15: =IFERROR(VLOOKUP("SD4_SHIPMENT",'Company 12'!$B:$E,4,0),"") -> 1 | AO15: =IFERROR(VLOOKUP("SD5_LEAD",'Company 12'!$B:$E,4,0),"") -> 0 | AP15: =IFERROR(VLOOKUP("SD6_CONJOINT",'Company 12'!$B:$E,4,0),"") -> 0
B16: Company 13 | C16: =IFERROR(VLOOKUP("Interviewee Position",'Company 13'!$B:$C,2,0),"") -> Data Lead / Head of IT & ERP | D16: =IFERROR(VLOOKUP("Company Industry",'Company 13'!$B:$C,2,0),"") -> Pet Food Manufacturing | E16: =IFERROR(VLOOKUP("Company Sub-Industry",'Company 13'!$B:$C,2,0),"") -> Manufacturer | F16: =IFERROR(VLOOKUP("Company Size (Turnover)",'Company 13'!$B:$C,2,0),"") -> 140000000 | G16: =IFERROR(VLOOKUP("Country",'Company 13'!$B:$C,2,0),"") -> Belgium | H16: =IFERROR(VLOOKUP("B1_INTEREST",'Company 13'!$B:$E,4,0),"") -> 9 | I16: =IFERROR(VLOOKUP("B2_SHARING",'Company 13'!$B:$E,4,0),"") -> 1 | J16: =IFERROR(VLOOKUP("B3_MONETIZE",'Company 13'!$B:$E,4,0),"") -> 0 | K16: =IFERROR(VLOOKUP("B4_STRATEGIC",'Company 13'!$B:$E,4,0),"") -> 0 | L16: =IFERROR(VLOOKUP("M1_AUTOMATED",'Company 13'!$B:$E,4,0),"") -> 3 | M16: =IFERROR(VLOOKUP("M2_REALTIME",'Company 13'!$B:$E,4,0),"") -> 3 | N16: =IFERROR(VLOOKUP("M3_STRATEGIC",'Company 13'!$B:$E,4,0),"") -> 4 | O16: =IFERROR(VLOOKUP("M4_BREADTH",'Company 13'!$B:$E,4,0),"") -> 3 | P16: =IFERROR(VLOOKUP("M5_DATATYPES",'Company 13'!$B:$E,4,0),"") -> 4 | Q16: =IFERROR(VLOOKUP("M6_TRUST",'Company 13'!$B:$E,4,0),"") -> 2 | R16: =IFERROR(VLOOKUP("M7_BARRIERS",'Company 13'!$B:$E,4,0),"") -> 3 | S16: =IFERROR(VLOOKUP("M8_IMPACT",'Company 13'!$B:$E,4,0),"") -> 3 | T16: =IFERROR(VLOOKUP("M9_WILLINGNESS",'Company 13'!$B:$E,4,0),"") -> 9 | U16: =IFERROR(VLOOKUP("SV1_PRICING",'Company 13'!$B:$E,4,0),"") -> 0 | V16: =IFERROR(VLOOKUP("SV2_PROMOTIONS",'Company 13'!$B:$E,4,0),"") -> 1 | W16: =IFERROR(VLOOKUP("SV3_SUPPLYCHAIN",'Company 13'!$B:$E,4,0),"") -> 1 | X16: =IFERROR(VLOOKUP("SV4_CATEGORY",'Company 13'!$B:$E,4,0),"") -> 1 | Y16: =IFERROR(VLOOKUP("SV5_DEMAND",'Company 13'!$B:$E,4,0),"") -> 0 | Z16: =IFERROR(VLOOKUP("SV6_ACCOUNT",'Company 13'!$B:$E,4,0),"") -> 0 | AA16: =IFERROR(VLOOKUP("SV7_OPS",'Company 13'!$B:$E,4,0),"") -> 1 | AB16: =IFERROR(VLOOKUP("SC1_DATASENS",'Company 13'!$B:$E,4,0),"") -> 1 | AC16: =IFERROR(VLOOKUP("SC2_COMPLIANCE",'Company 13'!$B:$E,4,0),"") -> 1 | AD16: =IFERROR(VLOOKUP("SC3_TRUST",'Company 13'!$B:$E,4,0),"") -> 1 | AE16: =IFERROR(VLOOKUP("SC4_DATAPROC",'Company 13'!$B:$E,4,0),"") -> 1 | AF16: =IFERROR(VLOOKUP("SF1_REALTIME",'Company 13'!$B:$E,4,0),"") -> 0 | AG16: =IFERROR(VLOOKUP("SF2_ACCESS",'Company 13'!$B:$E,4,0),"") -> 1 | AH16: =IFERROR(VLOOKUP("SF3_UX",'Company 13'!$B:$E,4,0),"") -> 0 | AI16: =IFERROR(VLOOKUP("SF4_DECISION",'Company 13'!$B:$E,4,0),"") -> 1 | AJ16: =IFERROR(VLOOKUP("SF5_MASKING",'Company 13'!$B:$E,4,0),"") -> 1 | AK16: =IFERROR(VLOOKUP("SD1_TRENDS",'Company 13'!$B:$E,4,0),"") -> 1 | AL16: =IFERROR(VLOOKUP("SD2_MARKET",'Company 13'!$B:$E,4,0),"") -> 1 | AM16: =IFERROR(VLOOKUP("SD3_CATEGORY",'Company 13'!$B:$E,4,0),"") -> 1 | AN16: =IFERROR(VLOOKUP("SD4_SHIPMENT",'Company 13'!$B:$E,4,0),"") -> 1 | AO16: =IFERROR(VLOOKUP("SD5_LEAD",'Company 13'!$B:$E,4,0),"") -> 1 | AP16: =IFERROR(VLOOKUP("SD6_CONJOINT",'Company 13'!$B:$E,4,0),"") -> 0
B17: Company 14 | C17: =IFERROR(VLOOKUP("Interviewee Position",#REF!,2,0),"") | D17: =IFERROR(VLOOKUP("Company Industry",#REF!,2,0),"") | E17: =IFERROR(VLOOKUP("Company Sub-Industry",#REF!,2,0),"") | F17: =IFERROR(VLOOKUP("Company Size (Turnover)",#REF!,2,0),"") | G17: =IFERROR(VLOOKUP("Country",#REF!,2,0),"") | H17: =IFERROR(VLOOKUP("B1_INTEREST",#REF!,4,0),"") | I17: =IFERROR(VLOOKUP("B2_SHARING",#REF!,4,0),"") | J17: =IFERROR(VLOOKUP("B3_MONETIZE",#REF!,4,0),"") | K17: =IFERROR(VLOOKUP("B4_STRATEGIC",#REF!,4,0),"") | L17: =IFERROR(VLOOKUP("M1_AUTOMATED",#REF!,4,0),"") | M17: =IFERROR(VLOOKUP("M2_REALTIME",#REF!,4,0),"") | N17: =IFERROR(VLOOKUP("M3_STRATEGIC",#REF!,4,0),"") | O17: =IFERROR(VLOOKUP("M4_BREADTH",#REF!,4,0),"") | P17: =IFERROR(VLOOKUP("M5_DATATYPES",#REF!,4,0),"") | Q17: =IFERROR(VLOOKUP("M6_TRUST",#REF!,4,0),"") | R17: =IFERROR(VLOOKUP("M7_BARRIERS",#REF!,4,0),"") | S17: =IFERROR(VLOOKUP("M8_IMPACT",#REF!,4,0),"") | T17: =IFERROR(VLOOKUP("M9_WILLINGNESS",#REF!,4,0),"") | U17: =IFERROR(VLOOKUP("SV1_PRICING",#REF!,4,0),"") | V17: =IFERROR(VLOOKUP("SV2_PROMOTIONS",#REF!,4,0),"") | W17: =IFERROR(VLOOKUP("SV3_SUPPLYCHAIN",#REF!,4,0),"") | X17: =IFERROR(VLOOKUP("SV4_CATEGORY",#REF!,4,0),"") | Y17: =IFERROR(VLOOKUP("SV5_DEMAND",#REF!,4,0),"") | Z17: =IFERROR(VLOOKUP("SV6_ACCOUNT",#REF!,4,0),"") | AA17: =IFERROR(VLOOKUP("SV7_OPS",#REF!,4,0),"") | AB17: =IFERROR(VLOOKUP("SC1_DATASENS",#REF!,4,0),"") | AC17: =IFERROR(VLOOKUP("SC2_COMPLIANCE",#REF!,4,0),"") | AD17: =IFERROR(VLOOKUP("SC3_TRUST",#REF!,4,0),"") | AE17: =IFERROR(VLOOKUP("SC4_DATAPROC",#REF!,4,0),"") | AF17: =IFERROR(VLOOKUP("SF1_REALTIME",#REF!,4,0),"") | AG17: =IFERROR(VLOOKUP("SF2_ACCESS",#REF!,4,0),"") | AH17: =IFERROR(VLOOKUP("SF3_UX",#REF!,4,0),"") | AI17: =IFERROR(VLOOKUP("SF4_DECISION",#REF!,4,0),"") | AJ17: =IFERROR(VLOOKUP("SF5_MASKING",#REF!,4,0),"") | AK17: =IFERROR(VLOOKUP("SD1_TRENDS",#REF!,4,0),"") | AL17: =IFERROR(VLOOKUP("SD2_MARKET",#REF!,4,0),"") | AM17: =IFERROR(VLOOKUP("SD3_CATEGORY",#REF!,4,0),"") | AN17: =IFERROR(VLOOKUP("SD4_SHIPMENT",#REF!,4,0),"") | AO17: =IFERROR(VLOOKUP("SD5_LEAD",#REF!,4,0),"") | AP17: =IFERROR(VLOOKUP("SD6_CONJOINT",#REF!,4,0),"")
B18: Company 15 | C18: =IFERROR(VLOOKUP("Interviewee Position",#REF!,2,0),"") | D18: =IFERROR(VLOOKUP("Company Industry",#REF!,2,0),"") | E18: =IFERROR(VLOOKUP("Company Sub-Industry",#REF!,2,0),"") | F18: =IFERROR(VLOOKUP("Company Size (Turnover)",#REF!,2,0),"") | G18: =IFERROR(VLOOKUP("Country",#REF!,2,0),"") | H18: =IFERROR(VLOOKUP("B1_INTEREST",#REF!,4,0),"") | I18: =IFERROR(VLOOKUP("B2_SHARING",#REF!,4,0),"") | J18: =IFERROR(VLOOKUP("B3_MONETIZE",#REF!,4,0),"") | K18: =IFERROR(VLOOKUP("B4_STRATEGIC",#REF!,4,0),"") | L18: =IFERROR(VLOOKUP("M1_AUTOMATED",#REF!,4,0),"") | M18: =IFERROR(VLOOKUP("M2_REALTIME",#REF!,4,0),"") | N18: =IFERROR(VLOOKUP("M3_STRATEGIC",#REF!,4,0),"") | O18: =IFERROR(VLOOKUP("M4_BREADTH",#REF!,4,0),"") | P18: =IFERROR(VLOOKUP("M5_DATATYPES",#REF!,4,0),"") | Q18: =IFERROR(VLOOKUP("M6_TRUST",#REF!,4,0),"") | R18: =IFERROR(VLOOKUP("M7_BARRIERS",#REF!,4,0),"") | S18: =IFERROR(VLOOKUP("M8_IMPACT",#REF!,4,0),"") | T18: =IFERROR(VLOOKUP("M9_WILLINGNESS",#REF!,4,0),"") | U18: =IFERROR(VLOOKUP("SV1_PRICING",#REF!,4,0),"") | V18: =IFERROR(VLOOKUP("SV2_PROMOTIONS",#REF!,4,0),"") | W18: =IFERROR(VLOOKUP("SV3_SUPPLYCHAIN",#REF!,4,0),"") | X18: =IFERROR(VLOOKUP("SV4_CATEGORY",#REF!,4,0),"") | Y18: =IFERROR(VLOOKUP("SV5_DEMAND",#REF!,4,0),"") | Z18: =IFERROR(VLOOKUP("SV6_ACCOUNT",#REF!,4,0),"") | AA18: =IFERROR(VLOOKUP("SV7_OPS",#REF!,4,0),"") | AB18: =IFERROR(VLOOKUP("SC1_DATASENS",#REF!,4,0),"") | AC18: =IFERROR(VLOOKUP("SC2_COMPLIANCE",#REF!,4,0),"") | AD18: =IFERROR(VLOOKUP("SC3_TRUST",#REF!,4,0),"") | AE18: =IFERROR(VLOOKUP("SC4_DATAPROC",#REF!,4,0),"") | AF18: =IFERROR(VLOOKUP("SF1_REALTIME",#REF!,4,0),"") | AG18: =IFERROR(VLOOKUP("SF2_ACCESS",#REF!,4,0),"") | AH18: =IFERROR(VLOOKUP("SF3_UX",#REF!,4,0),"") | AI18: =IFERROR(VLOOKUP("SF4_DECISION",#REF!,4,0),"") | AJ18: =IFERROR(VLOOKUP("SF5_MASKING",#REF!,4,0),"") | AK18: =IFERROR(VLOOKUP("SD1_TRENDS",#REF!,4,0),"") | AL18: =IFERROR(VLOOKUP("SD2_MARKET",#REF!,4,0),"") | AM18: =IFERROR(VLOOKUP("SD3_CATEGORY",#REF!,4,0),"") | AN18: =IFERROR(VLOOKUP("SD4_SHIPMENT",#REF!,4,0),"") | AO18: =IFERROR(VLOOKUP("SD5_LEAD",#REF!,4,0),"") | AP18: =IFERROR(VLOOKUP("SD6_CONJOINT",#REF!,4,0),"")
B19: Company 16 | C19: =IFERROR(VLOOKUP("Interviewee Position",#REF!,2,0),"") | D19: =IFERROR(VLOOKUP("Company Industry",#REF!,2,0),"") | E19: =IFERROR(VLOOKUP("Company Sub-Industry",#REF!,2,0),"") | F19: =IFERROR(VLOOKUP("Company Size (Turnover)",#REF!,2,0),"") | G19: =IFERROR(VLOOKUP("Country",#REF!,2,0),"") | H19: =IFERROR(VLOOKUP("B1_INTEREST",#REF!,4,0),"") | I19: =IFERROR(VLOOKUP("B2_SHARING",#REF!,4,0),"") | J19: =IFERROR(VLOOKUP("B3_MONETIZE",#REF!,4,0),"") | K19: =IFERROR(VLOOKUP("B4_STRATEGIC",#REF!,4,0),"") | L19: =IFERROR(VLOOKUP("M1_AUTOMATED",#REF!,4,0),"") | M19: =IFERROR(VLOOKUP("M2_REALTIME",#REF!,4,0),"") | N19: =IFERROR(VLOOKUP("M3_STRATEGIC",#REF!,4,0),"") | O19: =IFERROR(VLOOKUP("M4_BREADTH",#REF!,4,0),"") | P19: =IFERROR(VLOOKUP("M5_DATATYPES",#REF!,4,0),"") | Q19: =IFERROR(VLOOKUP("M6_TRUST",#REF!,4,0),"") | R19: =IFERROR(VLOOKUP("M7_BARRIERS",#REF!,4,0),"") | S19: =IFERROR(VLOOKUP("M8_IMPACT",#REF!,4,0),"") | T19: =IFERROR(VLOOKUP("M9_WILLINGNESS",#REF!,4,0),"") | U19: =IFERROR(VLOOKUP("SV1_PRICING",#REF!,4,0),"") | V19: =IFERROR(VLOOKUP("SV2_PROMOTIONS",#REF!,4,0),"") | W19: =IFERROR(VLOOKUP("SV3_SUPPLYCHAIN",#REF!,4,0),"") | X19: =IFERROR(VLOOKUP("SV4_CATEGORY",#REF!,4,0),"") | Y19: =IFERROR(VLOOKUP("SV5_DEMAND",#REF!,4,0),"") | Z19: =IFERROR(VLOOKUP("SV6_ACCOUNT",#REF!,4,0),"") | AA19: =IFERROR(VLOOKUP("SV7_OPS",#REF!,4,0),"") | AB19: =IFERROR(VLOOKUP("SC1_DATASENS",#REF!,4,0),"") | AC19: =IFERROR(VLOOKUP("SC2_COMPLIANCE",#REF!,4,0),"") | AD19: =IFERROR(VLOOKUP("SC3_TRUST",#REF!,4,0),"") | AE19: =IFERROR(VLOOKUP("SC4_DATAPROC",#REF!,4,0),"") | AF19: =IFERROR(VLOOKUP("SF1_REALTIME",#REF!,4,0),"") | AG19: =IFERROR(VLOOKUP("SF2_ACCESS",#REF!,4,0),"") | AH19: =IFERROR(VLOOKUP("SF3_UX",#REF!,4,0),"") | AI19: =IFERROR(VLOOKUP("SF4_DECISION",#REF!,4,0),"") | AJ19: =IFERROR(VLOOKUP("SF5_MASKING",#REF!,4,0),"") | AK19: =IFERROR(VLOOKUP("SD1_TRENDS",#REF!,4,0),"") | AL19: =IFERROR(VLOOKUP("SD2_MARKET",#REF!,4,0),"") | AM19: =IFERROR(VLOOKUP("SD3_CATEGORY",#REF!,4,0),"") | AN19: =IFERROR(VLOOKUP("SD4_SHIPMENT",#REF!,4,0),"") | AO19: =IFERROR(VLOOKUP("SD5_LEAD",#REF!,4,0),"") | AP19: =IFERROR(VLOOKUP("SD6_CONJOINT",#REF!,4,0),"")
B20: Company 17 | C20: =IFERROR(VLOOKUP("Interviewee Position",#REF!,2,0),"") | D20: =IFERROR(VLOOKUP("Company Industry",#REF!,2,0),"") | E20: =IFERROR(VLOOKUP("Company Sub-Industry",#REF!,2,0),"") | F20: =IFERROR(VLOOKUP("Company Size (Turnover)",#REF!,2,0),"") | G20: =IFERROR(VLOOKUP("Country",#REF!,2,0),"") | H20: =IFERROR(VLOOKUP("B1_INTEREST",#REF!,4,0),"") | I20: =IFERROR(VLOOKUP("B2_SHARING",#REF!,4,0),"") | J20: =IFERROR(VLOOKUP("B3_MONETIZE",#REF!,4,0),"") | K20: =IFERROR(VLOOKUP("B4_STRATEGIC",#REF!,4,0),"") | L20: =IFERROR(VLOOKUP("M1_AUTOMATED",#REF!,4,0),"") | M20: =IFERROR(VLOOKUP("M2_REALTIME",#REF!,4,0),"") | N20: =IFERROR(VLOOKUP("M3_STRATEGIC",#REF!,4,0),"") | O20: =IFERROR(VLOOKUP("M4_BREADTH",#REF!,4,0),"") | P20: =IFERROR(VLOOKUP("M5_DATATYPES",#REF!,4,0),"") | Q20: =IFERROR(VLOOKUP("M6_TRUST",#REF!,4,0),"") | R20: =IFERROR(VLOOKUP("M7_BARRIERS",#REF!,4,0),"") | S20: =IFERROR(VLOOKUP("M8_IMPACT",#REF!,4,0),"") | T20: =IFERROR(VLOOKUP("M9_WILLINGNESS",#REF!,4,0),"") | U20: =IFERROR(VLOOKUP("SV1_PRICING",#REF!,4,0),"") | V20: =IFERROR(VLOOKUP("SV2_PROMOTIONS",#REF!,4,0),"") | W20: =IFERROR(VLOOKUP("SV3_SUPPLYCHAIN",#REF!,4,0),"") | X20: =IFERROR(VLOOKUP("SV4_CATEGORY",#REF!,4,0),"") | Y20: =IFERROR(VLOOKUP("SV5_DEMAND",#REF!,4,0),"") | Z20: =IFERROR(VLOOKUP("SV6_ACCOUNT",#REF!,4,0),"") | AA20: =IFERROR(VLOOKUP("SV7_OPS",#REF!,4,0),"") | AB20: =IFERROR(VLOOKUP("SC1_DATASENS",#REF!,4,0),"") | AC20: =IFERROR(VLOOKUP("SC2_COMPLIANCE",#REF!,4,0),"") | AD20: =IFERROR(VLOOKUP("SC3_TRUST",#REF!,4,0),"") | AE20: =IFERROR(VLOOKUP("SC4_DATAPROC",#REF!,4,0),"") | AF20: =IFERROR(VLOOKUP("SF1_REALTIME",#REF!,4,0),"") | AG20: =IFERROR(VLOOKUP("SF2_ACCESS",#REF!,4,0),"") | AH20: =IFERROR(VLOOKUP("SF3_UX",#REF!,4,0),"") | AI20: =IFERROR(VLOOKUP("SF4_DECISION",#REF!,4,0),"") | AJ20: =IFERROR(VLOOKUP("SF5_MASKING",#REF!,4,0),"") | AK20: =IFERROR(VLOOKUP("SD1_TRENDS",#REF!,4,0),"") | AL20: =IFERROR(VLOOKUP("SD2_MARKET",#REF!,4,0),"") | AM20: =IFERROR(VLOOKUP("SD3_CATEGORY",#REF!,4,0),"") | AN20: =IFERROR(VLOOKUP("SD4_SHIPMENT",#REF!,4,0),"") | AO20: =IFERROR(VLOOKUP("SD5_LEAD",#REF!,4,0),"") | AP20: =IFERROR(VLOOKUP("SD6_CONJOINT",#REF!,4,0),"")
